Traceback (most recent call last):
  File "/root/work/clickhouse_test copy.py", line 155, in <module>
    start = datetime.datetime.strptime('2024-03-00 00:00:00', '%Y-%m-%d %H:%M:%S')
  File "/usr/lib/python3.10/_strptime.py", line 568, in _strptime_datetime
    tt, fraction, gmtoff_fraction = _strptime(data_string, format)
  File "/usr/lib/python3.10/_strptime.py", line 349, in _strptime
    raise ValueError("time data %r does not match format %r" %
ValueError: time data '2024-03-00 00:00:00' does not match format '%Y-%m-%d %H:%M:%S'
Traceback (most recent call last):
  File "/root/work/clickhouse_test copy.py", line 153, in <module>
    creat_table()
  File "/root/work/clickhouse_test copy.py", line 131, in creat_table
    get_clickhouse_client().command(
  File "/usr/local/lib/python3.10/dist-packages/clickhouse_connect/driver/httpclient.py", line 336, in command
    response = self._raw_request(payload, params, headers, method, fields=fields)
  File "/usr/local/lib/python3.10/dist-packages/clickhouse_connect/driver/httpclient.py", line 438, in _raw_request
    self._error_handler(response)
  File "/usr/local/lib/python3.10/dist-packages/clickhouse_connect/driver/httpclient.py", line 362, in _error_handler
    raise OperationalError(err_str) if retried else DatabaseError(err_str) from None
clickhouse_connect.driver.exceptions.DatabaseError: :HTTPDriver for http://localhost:8123 returned response code 500)
 Code: 478. DB::Exception: Unknown storage policy `local`. (UNKNOWN_POLICY) (version 24.3.2.23 (official build))

